False
Outside market hours; skipping crossover check.
False
Outside market hours; skipping crossover check.
False
Breakout check complete.
False
Breakout check complete.
False
Breakout check complete.
False
Breakout check complete.
False
Breakout check complete.
False
Breakout check complete.
False
Breakout check complete.
False
Breakout check complete.
False
Breakout check complete.
False
IN last_bar high
Breakout check complete.
False
Order placed: 44 shares of TATAMOTORS at approx ₹682.50
{'dhanClientId': '1102279413', 'transactionType': 'BUY', 'exchangeSegment': 'NSE_EQ', 'productType': 'CNC', 'orderType': 'MARKET', 'validity': 'DAY', 'securityId': '3456', 'quantity': 44, 'price': 682.5, 'triggerPrice': 682.5, 'afterMarketOrder': False}
Order placed for 8amitjain@gmail.com: 44 shares of TATAMOTORS at ₹682.50
Order placed: 44 shares of TATAMOTORS at approx ₹682.50
{'dhanClientId': '1100991549', 'transactionType': 'BUY', 'exchangeSegment': 'NSE_EQ', 'productType': 'CNC', 'orderType': 'MARKET', 'validity': 'DAY', 'securityId': '3456', 'quantity': 44, 'price': 682.5, 'triggerPrice': 682.5, 'afterMarketOrder': False}
Order placed for geometriya.analysis@gmail.com: 44 shares of TATAMOTORS at ₹682.50
Breakout check complete.
False
IN last_bar high
Breakout check complete.
False
Order placed: 38 shares of TATAMOTORS at approx ₹684.25
{'dhanClientId': '1102279413', 'transactionType': 'BUY', 'exchangeSegment': 'NSE_EQ', 'productType': 'CNC', 'orderType': 'MARKET', 'validity': 'DAY', 'securityId': '3456', 'quantity': 38, 'price': 684.25, 'triggerPrice': 684.25, 'afterMarketOrder': False}
Order placed for 8amitjain@gmail.com: 38 shares of TATAMOTORS at ₹684.25
Order placed: 38 shares of TATAMOTORS at approx ₹684.25
{'dhanClientId': '1100991549', 'transactionType': 'BUY', 'exchangeSegment': 'NSE_EQ', 'productType': 'CNC', 'orderType': 'MARKET', 'validity': 'DAY', 'securityId': '3456', 'quantity': 38, 'price': 684.25, 'triggerPrice': 684.25, 'afterMarketOrder': False}
Order placed for geometriya.analysis@gmail.com: 38 shares of TATAMOTORS at ₹684.25
Breakout check complete.
False
Breakout check complete.
False
IN last_bar high
Breakout check complete.
False
Order placed: 90 shares of RVNL at approx ₹378.65
{'dhanClientId': '1102279413', 'transactionType': 'BUY', 'exchangeSegment': 'NSE_EQ', 'productType': 'CNC', 'orderType': 'MARKET', 'validity': 'DAY', 'securityId': '9552', 'quantity': 90, 'price': 378.65, 'triggerPrice': 378.65, 'afterMarketOrder': False}
Order placed for 8amitjain@gmail.com: 90 shares of RVNL at ₹378.65
Order placed: 90 shares of RVNL at approx ₹378.65
{'dhanClientId': '1100991549', 'transactionType': 'BUY', 'exchangeSegment': 'NSE_EQ', 'productType': 'CNC', 'orderType': 'MARKET', 'validity': 'DAY', 'securityId': '9552', 'quantity': 90, 'price': 378.65, 'triggerPrice': 378.65, 'afterMarketOrder': False}
Order placed for geometriya.analysis@gmail.com: 90 shares of RVNL at ₹378.65
Breakout check complete.
False
Order placed: 89 shares of RVNL at approx ₹378.70
{'dhanClientId': '1102279413', 'transactionType': 'BUY', 'exchangeSegment': 'NSE_EQ', 'productType': 'CNC', 'orderType': 'MARKET', 'validity': 'DAY', 'securityId': '9552', 'quantity': 89, 'price': 378.7, 'triggerPrice': 378.7, 'afterMarketOrder': False}
Order placed for 8amitjain@gmail.com: 89 shares of RVNL at ₹378.70
Order placed: 89 shares of RVNL at approx ₹378.70
{'dhanClientId': '1100991549', 'transactionType': 'BUY', 'exchangeSegment': 'NSE_EQ', 'productType': 'CNC', 'orderType': 'MARKET', 'validity': 'DAY', 'securityId': '9552', 'quantity': 89, 'price': 378.7, 'triggerPrice': 378.7, 'afterMarketOrder': False}
Order placed for geometriya.analysis@gmail.com: 89 shares of RVNL at ₹378.70
Breakout check complete.
False
IN last_bar high
Breakout check complete.
False
IN last_bar high
Breakout check complete.
False
Order placed: 97 shares of RVNL at approx ₹378.25
{'dhanClientId': '1102279413', 'transactionType': 'BUY', 'exchangeSegment': 'NSE_EQ', 'productType': 'CNC', 'orderType': 'MARKET', 'validity': 'DAY', 'securityId': '9552', 'quantity': 97, 'price': 378.25, 'triggerPrice': 378.25, 'afterMarketOrder': False}
Order placed for 8amitjain@gmail.com: 97 shares of RVNL at ₹378.25
Order placed: 97 shares of RVNL at approx ₹378.25
{'dhanClientId': '1100991549', 'transactionType': 'BUY', 'exchangeSegment': 'NSE_EQ', 'productType': 'CNC', 'orderType': 'MARKET', 'validity': 'DAY', 'securityId': '9552', 'quantity': 97, 'price': 378.25, 'triggerPrice': 378.25, 'afterMarketOrder': False}
Order placed for geometriya.analysis@gmail.com: 97 shares of RVNL at ₹378.25
Breakout check complete.
False
Order placed: 94 shares of RVNL at approx ₹378.40
{'dhanClientId': '1102279413', 'transactionType': 'BUY', 'exchangeSegment': 'NSE_EQ', 'productType': 'CNC', 'orderType': 'MARKET', 'validity': 'DAY', 'securityId': '9552', 'quantity': 94, 'price': 378.4, 'triggerPrice': 378.4, 'afterMarketOrder': False}
Order placed for 8amitjain@gmail.com: 94 shares of RVNL at ₹378.40
Order placed: 94 shares of RVNL at approx ₹378.40
{'dhanClientId': '1100991549', 'transactionType': 'BUY', 'exchangeSegment': 'NSE_EQ', 'productType': 'CNC', 'orderType': 'MARKET', 'validity': 'DAY', 'securityId': '9552', 'quantity': 94, 'price': 378.4, 'triggerPrice': 378.4, 'afterMarketOrder': False}
Order placed for geometriya.analysis@gmail.com: 94 shares of RVNL at ₹378.40
Breakout check complete.
False
IN last_bar high
Breakout check complete.
False
Outside market hours; skipping crossover check.
False
Outside market hours; skipping crossover check.
False
Outside market hours; skipping crossover check.
False
Outside market hours; skipping crossover check.
False
Outside market hours; skipping crossover check.
False
Outside market hours; skipping crossover check.
False
IN last_bar high
Breakout check complete.
False
IN last_bar high
Breakout check complete.
False
IN last_bar high
Breakout check complete.
False
IN last_bar high
Breakout check complete.
False
IN last_bar high
Breakout check complete.
False
IN last_bar high
Breakout check complete.
False
IN last_bar high
Breakout check complete.
False
IN last_bar high
Breakout check complete.
False
IN last_bar high
Breakout check complete.
False
[Attempt 1] Request failed: ('Connection aborted.', RemoteDisconnected('Remote end closed connection without response'))
IN last_bar high
Breakout check complete.
False
IN last_bar high
Breakout check complete.
False
IN last_bar high
Breakout check complete.
False
IN last_bar high
Breakout check complete.
False
IN last_bar high
Breakout check complete.
False
IN last_bar high
Breakout check complete.
False
IN last_bar high
Breakout check complete.
False
IN last_bar high
Breakout check complete.
False
[Attempt 1] Request failed: ('Connection aborted.', RemoteDisconnected('Remote end closed connection without response'))
IN last_bar high
Breakout check complete.
False
IN last_bar high
Breakout check complete.
False
IN last_bar high
Breakout check complete.
False
IN last_bar high
Breakout check complete.
False
IN last_bar high
Breakout check complete.
False
Outside market hours; skipping crossover check.
False
Outside market hours; skipping crossover check.
False
Outside market hours; skipping crossover check.
False
Outside market hours; skipping crossover check.
False
Outside market hours; skipping crossover check.
False
Outside market hours; skipping crossover check.
False
IN last_bar high
Breakout check complete.
False
IN last_bar high
Breakout check complete.
False
IN last_bar high
Breakout check complete.
False
Order placed: 35 shares of BHARATFORG at approx ₹1217.10
{'dhanClientId': '1100991549', 'transactionType': 'BUY', 'exchangeSegment': 'NSE_EQ', 'productType': 'CNC', 'orderType': 'MARKET', 'validity': 'DAY', 'securityId': '422', 'quantity': 35, 'price': 1217.1, 'triggerPrice': 1217.1, 'afterMarketOrder': False}
Order placed for geometriya.analysis@gmail.com: 35 shares of BHARATFORG at ₹1217.10
Order placed: 35 shares of BHARATFORG at approx ₹1217.10
{'dhanClientId': '1102279413', 'transactionType': 'BUY', 'exchangeSegment': 'NSE_EQ', 'productType': 'CNC', 'orderType': 'MARKET', 'validity': 'DAY', 'securityId': '422', 'quantity': 35, 'price': 1217.1, 'triggerPrice': 1217.1, 'afterMarketOrder': False}
Order placed for 8amitjain@gmail.com: 35 shares of BHARATFORG at ₹1217.10
[Attempt 1] Request failed: 401 Client Error:  for url: https://api.dhan.co/v2/charts/intraday
[Attempt 2] Request failed: 401 Client Error:  for url: https://api.dhan.co/v2/charts/intraday
[Attempt 3] Request failed: 401 Client Error:  for url: https://api.dhan.co/v2/charts/intraday
Failed to fetch intraday OHLC after retries.
Breakout check complete.
False
IN last_bar high
IN last_bar high
Breakout check complete.
False
Order placed: 44 shares of BHARATFORG at approx ₹1214.20
{'dhanClientId': '1100991549', 'transactionType': 'BUY', 'exchangeSegment': 'NSE_EQ', 'productType': 'CNC', 'orderType': 'MARKET', 'validity': 'DAY', 'securityId': '422', 'quantity': 44, 'price': 1214.2, 'triggerPrice': 1214.2, 'afterMarketOrder': False}
Order placed for geometriya.analysis@gmail.com: 44 shares of BHARATFORG at ₹1214.20
Order placed: 44 shares of BHARATFORG at approx ₹1214.20
{'dhanClientId': '1102279413', 'transactionType': 'BUY', 'exchangeSegment': 'NSE_EQ', 'productType': 'CNC', 'orderType': 'MARKET', 'validity': 'DAY', 'securityId': '422', 'quantity': 44, 'price': 1214.2, 'triggerPrice': 1214.2, 'afterMarketOrder': False}
Order placed for 8amitjain@gmail.com: 44 shares of BHARATFORG at ₹1214.20
[Attempt 1] Request failed: 401 Client Error:  for url: https://api.dhan.co/v2/charts/intraday
[Attempt 2] Request failed: 401 Client Error:  for url: https://api.dhan.co/v2/charts/intraday
[Attempt 3] Request failed: 401 Client Error:  for url: https://api.dhan.co/v2/charts/intraday
Failed to fetch intraday OHLC after retries.
Breakout check complete.
False
IN last_bar high
Breakout check complete.
False
IN last_bar high
Breakout check complete.
False
IN last_bar high
Breakout check complete.
False
Order placed: 53 shares of RELIANCE at approx ₹1420.00
{'dhanClientId': '1100991549', 'transactionType': 'BUY', 'exchangeSegment': 'NSE_EQ', 'productType': 'CNC', 'orderType': 'MARKET', 'validity': 'DAY', 'securityId': '2885', 'quantity': 53, 'price': 1420.0, 'triggerPrice': 1420.0, 'afterMarketOrder': False}
Order placed for geometriya.analysis@gmail.com: 53 shares of RELIANCE at ₹1420.00
Order placed: 53 shares of RELIANCE at approx ₹1420.00
{'dhanClientId': '1102279413', 'transactionType': 'BUY', 'exchangeSegment': 'NSE_EQ', 'productType': 'CNC', 'orderType': 'MARKET', 'validity': 'DAY', 'securityId': '2885', 'quantity': 53, 'price': 1420.0, 'triggerPrice': 1420.0, 'afterMarketOrder': False}
Order placed for 8amitjain@gmail.com: 53 shares of RELIANCE at ₹1420.00
[Attempt 1] Request failed: 401 Client Error:  for url: https://api.dhan.co/v2/charts/intraday
[Attempt 2] Request failed: 401 Client Error:  for url: https://api.dhan.co/v2/charts/intraday
[Attempt 3] Request failed: 401 Client Error:  for url: https://api.dhan.co/v2/charts/intraday
Failed to fetch intraday OHLC after retries.
Breakout check complete.
False
Order placed: 48 shares of RELIANCE at approx ₹1421.00
{'dhanClientId': '1100991549', 'transactionType': 'BUY', 'exchangeSegment': 'NSE_EQ', 'productType': 'CNC', 'orderType': 'MARKET', 'validity': 'DAY', 'securityId': '2885', 'quantity': 48, 'price': 1421.0, 'triggerPrice': 1421.0, 'afterMarketOrder': False}
Order placed for geometriya.analysis@gmail.com: 48 shares of RELIANCE at ₹1421.00
Order placed: 48 shares of RELIANCE at approx ₹1421.00
{'dhanClientId': '1102279413', 'transactionType': 'BUY', 'exchangeSegment': 'NSE_EQ', 'productType': 'CNC', 'orderType': 'MARKET', 'validity': 'DAY', 'securityId': '2885', 'quantity': 48, 'price': 1421.0, 'triggerPrice': 1421.0, 'afterMarketOrder': False}
Order placed for 8amitjain@gmail.com: 48 shares of RELIANCE at ₹1421.00
[Attempt 1] Request failed: 401 Client Error:  for url: https://api.dhan.co/v2/charts/intraday
[Attempt 2] Request failed: 401 Client Error:  for url: https://api.dhan.co/v2/charts/intraday
[Attempt 3] Request failed: 401 Client Error:  for url: https://api.dhan.co/v2/charts/intraday
Failed to fetch intraday OHLC after retries.
Breakout check complete.
False
Order placed: 46 shares of RELIANCE at approx ₹1421.50
{'dhanClientId': '1100991549', 'transactionType': 'BUY', 'exchangeSegment': 'NSE_EQ', 'productType': 'CNC', 'orderType': 'MARKET', 'validity': 'DAY', 'securityId': '2885', 'quantity': 46, 'price': 1421.5, 'triggerPrice': 1421.5, 'afterMarketOrder': False}
Order placed for geometriya.analysis@gmail.com: 46 shares of RELIANCE at ₹1421.50
Order placed: 46 shares of RELIANCE at approx ₹1421.50
{'dhanClientId': '1102279413', 'transactionType': 'BUY', 'exchangeSegment': 'NSE_EQ', 'productType': 'CNC', 'orderType': 'MARKET', 'validity': 'DAY', 'securityId': '2885', 'quantity': 46, 'price': 1421.5, 'triggerPrice': 1421.5, 'afterMarketOrder': False}
Order placed for 8amitjain@gmail.com: 46 shares of RELIANCE at ₹1421.50
[Attempt 1] Request failed: 401 Client Error:  for url: https://api.dhan.co/v2/charts/intraday
[Attempt 2] Request failed: 401 Client Error:  for url: https://api.dhan.co/v2/charts/intraday
[Attempt 3] Request failed: 401 Client Error:  for url: https://api.dhan.co/v2/charts/intraday
Failed to fetch intraday OHLC after retries.
Breakout check complete.
False
Order placed: 44 shares of RELIANCE at approx ₹1421.90
{'dhanClientId': '1100991549', 'transactionType': 'BUY', 'exchangeSegment': 'NSE_EQ', 'productType': 'CNC', 'orderType': 'MARKET', 'validity': 'DAY', 'securityId': '2885', 'quantity': 44, 'price': 1421.9, 'triggerPrice': 1421.9, 'afterMarketOrder': False}
Order placed for geometriya.analysis@gmail.com: 44 shares of RELIANCE at ₹1421.90
Order placed: 44 shares of RELIANCE at approx ₹1421.90
{'dhanClientId': '1102279413', 'transactionType': 'BUY', 'exchangeSegment': 'NSE_EQ', 'productType': 'CNC', 'orderType': 'MARKET', 'validity': 'DAY', 'securityId': '2885', 'quantity': 44, 'price': 1421.9, 'triggerPrice': 1421.9, 'afterMarketOrder': False}
Order placed for 8amitjain@gmail.com: 44 shares of RELIANCE at ₹1421.90
[Attempt 1] Request failed: 401 Client Error:  for url: https://api.dhan.co/v2/charts/intraday
[Attempt 2] Request failed: 401 Client Error:  for url: https://api.dhan.co/v2/charts/intraday
[Attempt 3] Request failed: 401 Client Error:  for url: https://api.dhan.co/v2/charts/intraday
Failed to fetch intraday OHLC after retries.
Breakout check complete.
False
IN last_bar high
Breakout check complete.
False
IN last_bar high
Breakout check complete.
False
IN last_bar high
Breakout check complete.
False
IN last_bar high
Breakout check complete.
False
Order placed: 2500 shares of RVNL at approx ₹373.30
{'dhanClientId': '1100991549', 'transactionType': 'BUY', 'exchangeSegment': 'NSE_EQ', 'productType': 'CNC', 'orderType': 'MARKET', 'validity': 'DAY', 'securityId': '9552', 'quantity': 2500, 'price': 373.3, 'triggerPrice': 373.3, 'afterMarketOrder': False}
Order placed for geometriya.analysis@gmail.com: 2500 shares of RVNL at ₹373.30
Order placed: 2500 shares of RVNL at approx ₹373.30
{'dhanClientId': '1102279413', 'transactionType': 'BUY', 'exchangeSegment': 'NSE_EQ', 'productType': 'CNC', 'orderType': 'MARKET', 'validity': 'DAY', 'securityId': '9552', 'quantity': 2500, 'price': 373.3, 'triggerPrice': 373.3, 'afterMarketOrder': False}
Order placed for 8amitjain@gmail.com: 2500 shares of RVNL at ₹373.30
Breakout check complete.
False
IN last_bar high
Breakout check complete.
False
IN last_bar high
Breakout check complete.
False
IN last_bar high
Breakout check complete.
False
IN last_bar high
Breakout check complete.
False
Outside market hours; skipping crossover check.
False
Outside market hours; skipping crossover check.
False
Outside market hours; skipping crossover check.
False
Outside market hours; skipping crossover check.
False
Outside market hours; skipping crossover check.
False
Outside market hours; skipping crossover check.
False
Order placed: 188 shares of RVNL at approx ₹375.75
{'dhanClientId': '1100991549', 'transactionType': 'BUY', 'exchangeSegment': 'NSE_EQ', 'productType': 'CNC', 'orderType': 'MARKET', 'validity': 'DAY', 'securityId': '9552', 'quantity': 188, 'price': 375.75, 'triggerPrice': 375.75, 'afterMarketOrder': False}
Order placed for geometriya.analysis@gmail.com: 188 shares of RVNL at ₹375.75
Order placed: 188 shares of RVNL at approx ₹375.75
{'dhanClientId': '1102279413', 'transactionType': 'BUY', 'exchangeSegment': 'NSE_EQ', 'productType': 'CNC', 'orderType': 'MARKET', 'validity': 'DAY', 'securityId': '9552', 'quantity': 188, 'price': 375.75, 'triggerPrice': 375.75, 'afterMarketOrder': False}
Order placed for 8amitjain@gmail.com: 188 shares of RVNL at ₹375.75
Breakout check complete.
False
Breakout check complete.
False
Breakout check complete.
False
Breakout check complete.
False
Breakout check complete.
False
Breakout check complete.
False
Breakout check complete.
False
Breakout check complete.
False
Breakout check complete.
False
Breakout check complete.
False
Breakout check complete.
False
Breakout check complete.
False
Breakout check complete.
False
Breakout check complete.
False
Breakout check complete.
False
Breakout check complete.
False
Breakout check complete.
False
Traceback (most recent call last):
  File "/home/ubuntu/Geo-Algo/venv/lib/python3.8/site-packages/django/db/backends/base/base.py", line 288, in ensure_connection
    self.connect()
  File "/home/ubuntu/Geo-Algo/venv/lib/python3.8/site-packages/django/utils/asyncio.py", line 26, in inner
    return func(*args, **kwargs)
  File "/home/ubuntu/Geo-Algo/venv/lib/python3.8/site-packages/django/db/backends/base/base.py", line 269, in connect
    self.connection = self.get_new_connection(conn_params)
  File "/home/ubuntu/Geo-Algo/venv/lib/python3.8/site-packages/django/utils/asyncio.py", line 26, in inner
    return func(*args, **kwargs)
  File "/home/ubuntu/Geo-Algo/venv/lib/python3.8/site-packages/django/db/backends/postgresql/base.py", line 275, in get_new_connection
    connection = self.Database.connect(**conn_params)
  File "/home/ubuntu/Geo-Algo/venv/lib/python3.8/site-packages/psycopg2/__init__.py", line 122, in connect
    conn = _connect(dsn, connection_factory=connection_factory, **kwasync)
psycopg2.OperationalError: connection to server at "13.126.174.197", port 5432 failed: Network is unreachable
	Is the server running on that host and accepting TCP/IP connections?


The above exception was the direct cause of the following exception:

Traceback (most recent call last):
  File "/home/ubuntu/Geo-Algo/manage.py", line 22, in <module>
    main()
  File "/home/ubuntu/Geo-Algo/manage.py", line 18, in main
    execute_from_command_line(sys.argv)
  File "/home/ubuntu/Geo-Algo/venv/lib/python3.8/site-packages/django/core/management/__init__.py", line 442, in execute_from_command_line
    utility.execute()
  File "/home/ubuntu/Geo-Algo/venv/lib/python3.8/site-packages/django/core/management/__init__.py", line 436, in execute
    self.fetch_command(subcommand).run_from_argv(self.argv)
  File "/home/ubuntu/Geo-Algo/venv/lib/python3.8/site-packages/django/core/management/base.py", line 412, in run_from_argv
    self.execute(*args, **cmd_options)
  File "/home/ubuntu/Geo-Algo/venv/lib/python3.8/site-packages/django/core/management/base.py", line 458, in execute
    output = self.handle(*args, **options)
  File "/home/ubuntu/Geo-Algo/market/management/commands/check_break_high.py", line 134, in handle
    BreakoutChecker(settings.DATA_DHAN_ACCESS_TOKEN).run()
  File "/home/ubuntu/Geo-Algo/market/management/commands/check_break_high.py", line 28, in run
    for chk in recent:
  File "/home/ubuntu/Geo-Algo/venv/lib/python3.8/site-packages/django/db/models/query.py", line 398, in __iter__
    self._fetch_all()
  File "/home/ubuntu/Geo-Algo/venv/lib/python3.8/site-packages/django/db/models/query.py", line 1881, in _fetch_all
    self._result_cache = list(self._iterable_class(self))
  File "/home/ubuntu/Geo-Algo/venv/lib/python3.8/site-packages/django/db/models/query.py", line 91, in __iter__
    results = compiler.execute_sql(
  File "/home/ubuntu/Geo-Algo/venv/lib/python3.8/site-packages/django/db/models/sql/compiler.py", line 1560, in execute_sql
    cursor = self.connection.cursor()
  File "/home/ubuntu/Geo-Algo/venv/lib/python3.8/site-packages/django/utils/asyncio.py", line 26, in inner
    return func(*args, **kwargs)
  File "/home/ubuntu/Geo-Algo/venv/lib/python3.8/site-packages/django/db/backends/base/base.py", line 329, in cursor
    return self._cursor()
  File "/home/ubuntu/Geo-Algo/venv/lib/python3.8/site-packages/django/db/backends/base/base.py", line 305, in _cursor
    self.ensure_connection()
  File "/home/ubuntu/Geo-Algo/venv/lib/python3.8/site-packages/django/utils/asyncio.py", line 26, in inner
    return func(*args, **kwargs)
  File "/home/ubuntu/Geo-Algo/venv/lib/python3.8/site-packages/django/db/backends/base/base.py", line 288, in ensure_connection
    self.connect()
  File "/home/ubuntu/Geo-Algo/venv/lib/python3.8/site-packages/django/db/utils.py", line 91, in __exit__
    raise dj_exc_value.with_traceback(traceback) from exc_value
  File "/home/ubuntu/Geo-Algo/venv/lib/python3.8/site-packages/django/db/backends/base/base.py", line 288, in ensure_connection
    self.connect()
  File "/home/ubuntu/Geo-Algo/venv/lib/python3.8/site-packages/django/utils/asyncio.py", line 26, in inner
    return func(*args, **kwargs)
  File "/home/ubuntu/Geo-Algo/venv/lib/python3.8/site-packages/django/db/backends/base/base.py", line 269, in connect
    self.connection = self.get_new_connection(conn_params)
  File "/home/ubuntu/Geo-Algo/venv/lib/python3.8/site-packages/django/utils/asyncio.py", line 26, in inner
    return func(*args, **kwargs)
  File "/home/ubuntu/Geo-Algo/venv/lib/python3.8/site-packages/django/db/backends/postgresql/base.py", line 275, in get_new_connection
    connection = self.Database.connect(**conn_params)
  File "/home/ubuntu/Geo-Algo/venv/lib/python3.8/site-packages/psycopg2/__init__.py", line 122, in connect
    conn = _connect(dsn, connection_factory=connection_factory, **kwasync)
django.db.utils.OperationalError: connection to server at "13.126.174.197", port 5432 failed: Network is unreachable
	Is the server running on that host and accepting TCP/IP connections?

False
Traceback (most recent call last):
  File "/home/ubuntu/Geo-Algo/venv/lib/python3.8/site-packages/django/db/backends/base/base.py", line 288, in ensure_connection
    self.connect()
  File "/home/ubuntu/Geo-Algo/venv/lib/python3.8/site-packages/django/utils/asyncio.py", line 26, in inner
    return func(*args, **kwargs)
  File "/home/ubuntu/Geo-Algo/venv/lib/python3.8/site-packages/django/db/backends/base/base.py", line 269, in connect
    self.connection = self.get_new_connection(conn_params)
  File "/home/ubuntu/Geo-Algo/venv/lib/python3.8/site-packages/django/utils/asyncio.py", line 26, in inner
    return func(*args, **kwargs)
  File "/home/ubuntu/Geo-Algo/venv/lib/python3.8/site-packages/django/db/backends/postgresql/base.py", line 275, in get_new_connection
    connection = self.Database.connect(**conn_params)
  File "/home/ubuntu/Geo-Algo/venv/lib/python3.8/site-packages/psycopg2/__init__.py", line 122, in connect
    conn = _connect(dsn, connection_factory=connection_factory, **kwasync)
psycopg2.OperationalError: connection to server at "13.126.174.197", port 5432 failed: Network is unreachable
	Is the server running on that host and accepting TCP/IP connections?


The above exception was the direct cause of the following exception:

Traceback (most recent call last):
  File "/home/ubuntu/Geo-Algo/manage.py", line 22, in <module>
    main()
  File "/home/ubuntu/Geo-Algo/manage.py", line 18, in main
    execute_from_command_line(sys.argv)
  File "/home/ubuntu/Geo-Algo/venv/lib/python3.8/site-packages/django/core/management/__init__.py", line 442, in execute_from_command_line
    utility.execute()
  File "/home/ubuntu/Geo-Algo/venv/lib/python3.8/site-packages/django/core/management/__init__.py", line 436, in execute
    self.fetch_command(subcommand).run_from_argv(self.argv)
  File "/home/ubuntu/Geo-Algo/venv/lib/python3.8/site-packages/django/core/management/base.py", line 412, in run_from_argv
    self.execute(*args, **cmd_options)
  File "/home/ubuntu/Geo-Algo/venv/lib/python3.8/site-packages/django/core/management/base.py", line 458, in execute
    output = self.handle(*args, **options)
  File "/home/ubuntu/Geo-Algo/market/management/commands/check_break_high.py", line 134, in handle
    BreakoutChecker(settings.DATA_DHAN_ACCESS_TOKEN).run()
  File "/home/ubuntu/Geo-Algo/market/management/commands/check_break_high.py", line 28, in run
    for chk in recent:
  File "/home/ubuntu/Geo-Algo/venv/lib/python3.8/site-packages/django/db/models/query.py", line 398, in __iter__
    self._fetch_all()
  File "/home/ubuntu/Geo-Algo/venv/lib/python3.8/site-packages/django/db/models/query.py", line 1881, in _fetch_all
    self._result_cache = list(self._iterable_class(self))
  File "/home/ubuntu/Geo-Algo/venv/lib/python3.8/site-packages/django/db/models/query.py", line 91, in __iter__
    results = compiler.execute_sql(
  File "/home/ubuntu/Geo-Algo/venv/lib/python3.8/site-packages/django/db/models/sql/compiler.py", line 1560, in execute_sql
    cursor = self.connection.cursor()
  File "/home/ubuntu/Geo-Algo/venv/lib/python3.8/site-packages/django/utils/asyncio.py", line 26, in inner
    return func(*args, **kwargs)
  File "/home/ubuntu/Geo-Algo/venv/lib/python3.8/site-packages/django/db/backends/base/base.py", line 329, in cursor
    return self._cursor()
  File "/home/ubuntu/Geo-Algo/venv/lib/python3.8/site-packages/django/db/backends/base/base.py", line 305, in _cursor
    self.ensure_connection()
  File "/home/ubuntu/Geo-Algo/venv/lib/python3.8/site-packages/django/utils/asyncio.py", line 26, in inner
    return func(*args, **kwargs)
  File "/home/ubuntu/Geo-Algo/venv/lib/python3.8/site-packages/django/db/backends/base/base.py", line 288, in ensure_connection
    self.connect()
  File "/home/ubuntu/Geo-Algo/venv/lib/python3.8/site-packages/django/db/utils.py", line 91, in __exit__
    raise dj_exc_value.with_traceback(traceback) from exc_value
  File "/home/ubuntu/Geo-Algo/venv/lib/python3.8/site-packages/django/db/backends/base/base.py", line 288, in ensure_connection
    self.connect()
  File "/home/ubuntu/Geo-Algo/venv/lib/python3.8/site-packages/django/utils/asyncio.py", line 26, in inner
    return func(*args, **kwargs)
  File "/home/ubuntu/Geo-Algo/venv/lib/python3.8/site-packages/django/db/backends/base/base.py", line 269, in connect
    self.connection = self.get_new_connection(conn_params)
  File "/home/ubuntu/Geo-Algo/venv/lib/python3.8/site-packages/django/utils/asyncio.py", line 26, in inner
    return func(*args, **kwargs)
  File "/home/ubuntu/Geo-Algo/venv/lib/python3.8/site-packages/django/db/backends/postgresql/base.py", line 275, in get_new_connection
    connection = self.Database.connect(**conn_params)
  File "/home/ubuntu/Geo-Algo/venv/lib/python3.8/site-packages/psycopg2/__init__.py", line 122, in connect
    conn = _connect(dsn, connection_factory=connection_factory, **kwasync)
django.db.utils.OperationalError: connection to server at "13.126.174.197", port 5432 failed: Network is unreachable
	Is the server running on that host and accepting TCP/IP connections?

False
Traceback (most recent call last):
  File "/home/ubuntu/Geo-Algo/venv/lib/python3.8/site-packages/django/db/backends/base/base.py", line 288, in ensure_connection
    self.connect()
  File "/home/ubuntu/Geo-Algo/venv/lib/python3.8/site-packages/django/utils/asyncio.py", line 26, in inner
    return func(*args, **kwargs)
  File "/home/ubuntu/Geo-Algo/venv/lib/python3.8/site-packages/django/db/backends/base/base.py", line 269, in connect
    self.connection = self.get_new_connection(conn_params)
  File "/home/ubuntu/Geo-Algo/venv/lib/python3.8/site-packages/django/utils/asyncio.py", line 26, in inner
    return func(*args, **kwargs)
  File "/home/ubuntu/Geo-Algo/venv/lib/python3.8/site-packages/django/db/backends/postgresql/base.py", line 275, in get_new_connection
    connection = self.Database.connect(**conn_params)
  File "/home/ubuntu/Geo-Algo/venv/lib/python3.8/site-packages/psycopg2/__init__.py", line 122, in connect
    conn = _connect(dsn, connection_factory=connection_factory, **kwasync)
psycopg2.OperationalError: connection to server at "13.126.174.197", port 5432 failed: Network is unreachable
	Is the server running on that host and accepting TCP/IP connections?


The above exception was the direct cause of the following exception:

Traceback (most recent call last):
  File "/home/ubuntu/Geo-Algo/manage.py", line 22, in <module>
    main()
  File "/home/ubuntu/Geo-Algo/manage.py", line 18, in main
    execute_from_command_line(sys.argv)
  File "/home/ubuntu/Geo-Algo/venv/lib/python3.8/site-packages/django/core/management/__init__.py", line 442, in execute_from_command_line
    utility.execute()
  File "/home/ubuntu/Geo-Algo/venv/lib/python3.8/site-packages/django/core/management/__init__.py", line 436, in execute
    self.fetch_command(subcommand).run_from_argv(self.argv)
  File "/home/ubuntu/Geo-Algo/venv/lib/python3.8/site-packages/django/core/management/base.py", line 412, in run_from_argv
    self.execute(*args, **cmd_options)
  File "/home/ubuntu/Geo-Algo/venv/lib/python3.8/site-packages/django/core/management/base.py", line 458, in execute
    output = self.handle(*args, **options)
  File "/home/ubuntu/Geo-Algo/market/management/commands/check_break_high.py", line 134, in handle
    BreakoutChecker(settings.DATA_DHAN_ACCESS_TOKEN).run()
  File "/home/ubuntu/Geo-Algo/market/management/commands/check_break_high.py", line 28, in run
    for chk in recent:
  File "/home/ubuntu/Geo-Algo/venv/lib/python3.8/site-packages/django/db/models/query.py", line 398, in __iter__
    self._fetch_all()
  File "/home/ubuntu/Geo-Algo/venv/lib/python3.8/site-packages/django/db/models/query.py", line 1881, in _fetch_all
    self._result_cache = list(self._iterable_class(self))
  File "/home/ubuntu/Geo-Algo/venv/lib/python3.8/site-packages/django/db/models/query.py", line 91, in __iter__
    results = compiler.execute_sql(
  File "/home/ubuntu/Geo-Algo/venv/lib/python3.8/site-packages/django/db/models/sql/compiler.py", line 1560, in execute_sql
    cursor = self.connection.cursor()
  File "/home/ubuntu/Geo-Algo/venv/lib/python3.8/site-packages/django/utils/asyncio.py", line 26, in inner
    return func(*args, **kwargs)
  File "/home/ubuntu/Geo-Algo/venv/lib/python3.8/site-packages/django/db/backends/base/base.py", line 329, in cursor
    return self._cursor()
  File "/home/ubuntu/Geo-Algo/venv/lib/python3.8/site-packages/django/db/backends/base/base.py", line 305, in _cursor
    self.ensure_connection()
  File "/home/ubuntu/Geo-Algo/venv/lib/python3.8/site-packages/django/utils/asyncio.py", line 26, in inner
    return func(*args, **kwargs)
  File "/home/ubuntu/Geo-Algo/venv/lib/python3.8/site-packages/django/db/backends/base/base.py", line 288, in ensure_connection
    self.connect()
  File "/home/ubuntu/Geo-Algo/venv/lib/python3.8/site-packages/django/db/utils.py", line 91, in __exit__
    raise dj_exc_value.with_traceback(traceback) from exc_value
  File "/home/ubuntu/Geo-Algo/venv/lib/python3.8/site-packages/django/db/backends/base/base.py", line 288, in ensure_connection
    self.connect()
  File "/home/ubuntu/Geo-Algo/venv/lib/python3.8/site-packages/django/utils/asyncio.py", line 26, in inner
    return func(*args, **kwargs)
  File "/home/ubuntu/Geo-Algo/venv/lib/python3.8/site-packages/django/db/backends/base/base.py", line 269, in connect
    self.connection = self.get_new_connection(conn_params)
  File "/home/ubuntu/Geo-Algo/venv/lib/python3.8/site-packages/django/utils/asyncio.py", line 26, in inner
    return func(*args, **kwargs)
  File "/home/ubuntu/Geo-Algo/venv/lib/python3.8/site-packages/django/db/backends/postgresql/base.py", line 275, in get_new_connection
    connection = self.Database.connect(**conn_params)
  File "/home/ubuntu/Geo-Algo/venv/lib/python3.8/site-packages/psycopg2/__init__.py", line 122, in connect
    conn = _connect(dsn, connection_factory=connection_factory, **kwasync)
django.db.utils.OperationalError: connection to server at "13.126.174.197", port 5432 failed: Network is unreachable
	Is the server running on that host and accepting TCP/IP connections?

False
Traceback (most recent call last):
  File "/home/ubuntu/Geo-Algo/venv/lib/python3.8/site-packages/django/db/backends/base/base.py", line 288, in ensure_connection
    self.connect()
  File "/home/ubuntu/Geo-Algo/venv/lib/python3.8/site-packages/django/utils/asyncio.py", line 26, in inner
    return func(*args, **kwargs)
  File "/home/ubuntu/Geo-Algo/venv/lib/python3.8/site-packages/django/db/backends/base/base.py", line 269, in connect
    self.connection = self.get_new_connection(conn_params)
  File "/home/ubuntu/Geo-Algo/venv/lib/python3.8/site-packages/django/utils/asyncio.py", line 26, in inner
    return func(*args, **kwargs)
  File "/home/ubuntu/Geo-Algo/venv/lib/python3.8/site-packages/django/db/backends/postgresql/base.py", line 275, in get_new_connection
    connection = self.Database.connect(**conn_params)
  File "/home/ubuntu/Geo-Algo/venv/lib/python3.8/site-packages/psycopg2/__init__.py", line 122, in connect
    conn = _connect(dsn, connection_factory=connection_factory, **kwasync)
psycopg2.OperationalError: connection to server at "13.126.174.197", port 5432 failed: Network is unreachable
	Is the server running on that host and accepting TCP/IP connections?


The above exception was the direct cause of the following exception:

Traceback (most recent call last):
  File "/home/ubuntu/Geo-Algo/manage.py", line 22, in <module>
    main()
  File "/home/ubuntu/Geo-Algo/manage.py", line 18, in main
    execute_from_command_line(sys.argv)
  File "/home/ubuntu/Geo-Algo/venv/lib/python3.8/site-packages/django/core/management/__init__.py", line 442, in execute_from_command_line
    utility.execute()
  File "/home/ubuntu/Geo-Algo/venv/lib/python3.8/site-packages/django/core/management/__init__.py", line 436, in execute
    self.fetch_command(subcommand).run_from_argv(self.argv)
  File "/home/ubuntu/Geo-Algo/venv/lib/python3.8/site-packages/django/core/management/base.py", line 412, in run_from_argv
    self.execute(*args, **cmd_options)
  File "/home/ubuntu/Geo-Algo/venv/lib/python3.8/site-packages/django/core/management/base.py", line 458, in execute
    output = self.handle(*args, **options)
  File "/home/ubuntu/Geo-Algo/market/management/commands/check_break_high.py", line 134, in handle
    BreakoutChecker(settings.DATA_DHAN_ACCESS_TOKEN).run()
  File "/home/ubuntu/Geo-Algo/market/management/commands/check_break_high.py", line 28, in run
    for chk in recent:
  File "/home/ubuntu/Geo-Algo/venv/lib/python3.8/site-packages/django/db/models/query.py", line 398, in __iter__
    self._fetch_all()
  File "/home/ubuntu/Geo-Algo/venv/lib/python3.8/site-packages/django/db/models/query.py", line 1881, in _fetch_all
    self._result_cache = list(self._iterable_class(self))
  File "/home/ubuntu/Geo-Algo/venv/lib/python3.8/site-packages/django/db/models/query.py", line 91, in __iter__
    results = compiler.execute_sql(
  File "/home/ubuntu/Geo-Algo/venv/lib/python3.8/site-packages/django/db/models/sql/compiler.py", line 1560, in execute_sql
    cursor = self.connection.cursor()
  File "/home/ubuntu/Geo-Algo/venv/lib/python3.8/site-packages/django/utils/asyncio.py", line 26, in inner
    return func(*args, **kwargs)
  File "/home/ubuntu/Geo-Algo/venv/lib/python3.8/site-packages/django/db/backends/base/base.py", line 329, in cursor
    return self._cursor()
  File "/home/ubuntu/Geo-Algo/venv/lib/python3.8/site-packages/django/db/backends/base/base.py", line 305, in _cursor
    self.ensure_connection()
  File "/home/ubuntu/Geo-Algo/venv/lib/python3.8/site-packages/django/utils/asyncio.py", line 26, in inner
    return func(*args, **kwargs)
  File "/home/ubuntu/Geo-Algo/venv/lib/python3.8/site-packages/django/db/backends/base/base.py", line 288, in ensure_connection
    self.connect()
  File "/home/ubuntu/Geo-Algo/venv/lib/python3.8/site-packages/django/db/utils.py", line 91, in __exit__
    raise dj_exc_value.with_traceback(traceback) from exc_value
  File "/home/ubuntu/Geo-Algo/venv/lib/python3.8/site-packages/django/db/backends/base/base.py", line 288, in ensure_connection
    self.connect()
  File "/home/ubuntu/Geo-Algo/venv/lib/python3.8/site-packages/django/utils/asyncio.py", line 26, in inner
    return func(*args, **kwargs)
  File "/home/ubuntu/Geo-Algo/venv/lib/python3.8/site-packages/django/db/backends/base/base.py", line 269, in connect
    self.connection = self.get_new_connection(conn_params)
  File "/home/ubuntu/Geo-Algo/venv/lib/python3.8/site-packages/django/utils/asyncio.py", line 26, in inner
    return func(*args, **kwargs)
  File "/home/ubuntu/Geo-Algo/venv/lib/python3.8/site-packages/django/db/backends/postgresql/base.py", line 275, in get_new_connection
    connection = self.Database.connect(**conn_params)
  File "/home/ubuntu/Geo-Algo/venv/lib/python3.8/site-packages/psycopg2/__init__.py", line 122, in connect
    conn = _connect(dsn, connection_factory=connection_factory, **kwasync)
django.db.utils.OperationalError: connection to server at "13.126.174.197", port 5432 failed: Network is unreachable
	Is the server running on that host and accepting TCP/IP connections?

False
Traceback (most recent call last):
  File "/home/ubuntu/Geo-Algo/venv/lib/python3.8/site-packages/django/db/backends/base/base.py", line 288, in ensure_connection
    self.connect()
  File "/home/ubuntu/Geo-Algo/venv/lib/python3.8/site-packages/django/utils/asyncio.py", line 26, in inner
    return func(*args, **kwargs)
  File "/home/ubuntu/Geo-Algo/venv/lib/python3.8/site-packages/django/db/backends/base/base.py", line 269, in connect
    self.connection = self.get_new_connection(conn_params)
  File "/home/ubuntu/Geo-Algo/venv/lib/python3.8/site-packages/django/utils/asyncio.py", line 26, in inner
    return func(*args, **kwargs)
  File "/home/ubuntu/Geo-Algo/venv/lib/python3.8/site-packages/django/db/backends/postgresql/base.py", line 275, in get_new_connection
    connection = self.Database.connect(**conn_params)
  File "/home/ubuntu/Geo-Algo/venv/lib/python3.8/site-packages/psycopg2/__init__.py", line 122, in connect
    conn = _connect(dsn, connection_factory=connection_factory, **kwasync)
psycopg2.OperationalError: connection to server at "13.126.174.197", port 5432 failed: Network is unreachable
	Is the server running on that host and accepting TCP/IP connections?


The above exception was the direct cause of the following exception:

Traceback (most recent call last):
  File "/home/ubuntu/Geo-Algo/manage.py", line 22, in <module>
    main()
  File "/home/ubuntu/Geo-Algo/manage.py", line 18, in main
    execute_from_command_line(sys.argv)
  File "/home/ubuntu/Geo-Algo/venv/lib/python3.8/site-packages/django/core/management/__init__.py", line 442, in execute_from_command_line
    utility.execute()
  File "/home/ubuntu/Geo-Algo/venv/lib/python3.8/site-packages/django/core/management/__init__.py", line 436, in execute
    self.fetch_command(subcommand).run_from_argv(self.argv)
  File "/home/ubuntu/Geo-Algo/venv/lib/python3.8/site-packages/django/core/management/base.py", line 412, in run_from_argv
    self.execute(*args, **cmd_options)
  File "/home/ubuntu/Geo-Algo/venv/lib/python3.8/site-packages/django/core/management/base.py", line 458, in execute
    output = self.handle(*args, **options)
  File "/home/ubuntu/Geo-Algo/market/management/commands/check_break_high.py", line 134, in handle
    BreakoutChecker(settings.DATA_DHAN_ACCESS_TOKEN).run()
  File "/home/ubuntu/Geo-Algo/market/management/commands/check_break_high.py", line 28, in run
    for chk in recent:
  File "/home/ubuntu/Geo-Algo/venv/lib/python3.8/site-packages/django/db/models/query.py", line 398, in __iter__
    self._fetch_all()
  File "/home/ubuntu/Geo-Algo/venv/lib/python3.8/site-packages/django/db/models/query.py", line 1881, in _fetch_all
    self._result_cache = list(self._iterable_class(self))
  File "/home/ubuntu/Geo-Algo/venv/lib/python3.8/site-packages/django/db/models/query.py", line 91, in __iter__
    results = compiler.execute_sql(
  File "/home/ubuntu/Geo-Algo/venv/lib/python3.8/site-packages/django/db/models/sql/compiler.py", line 1560, in execute_sql
    cursor = self.connection.cursor()
  File "/home/ubuntu/Geo-Algo/venv/lib/python3.8/site-packages/django/utils/asyncio.py", line 26, in inner
    return func(*args, **kwargs)
  File "/home/ubuntu/Geo-Algo/venv/lib/python3.8/site-packages/django/db/backends/base/base.py", line 329, in cursor
    return self._cursor()
  File "/home/ubuntu/Geo-Algo/venv/lib/python3.8/site-packages/django/db/backends/base/base.py", line 305, in _cursor
    self.ensure_connection()
  File "/home/ubuntu/Geo-Algo/venv/lib/python3.8/site-packages/django/utils/asyncio.py", line 26, in inner
    return func(*args, **kwargs)
  File "/home/ubuntu/Geo-Algo/venv/lib/python3.8/site-packages/django/db/backends/base/base.py", line 288, in ensure_connection
    self.connect()
  File "/home/ubuntu/Geo-Algo/venv/lib/python3.8/site-packages/django/db/utils.py", line 91, in __exit__
    raise dj_exc_value.with_traceback(traceback) from exc_value
  File "/home/ubuntu/Geo-Algo/venv/lib/python3.8/site-packages/django/db/backends/base/base.py", line 288, in ensure_connection
    self.connect()
  File "/home/ubuntu/Geo-Algo/venv/lib/python3.8/site-packages/django/utils/asyncio.py", line 26, in inner
    return func(*args, **kwargs)
  File "/home/ubuntu/Geo-Algo/venv/lib/python3.8/site-packages/django/db/backends/base/base.py", line 269, in connect
    self.connection = self.get_new_connection(conn_params)
  File "/home/ubuntu/Geo-Algo/venv/lib/python3.8/site-packages/django/utils/asyncio.py", line 26, in inner
    return func(*args, **kwargs)
  File "/home/ubuntu/Geo-Algo/venv/lib/python3.8/site-packages/django/db/backends/postgresql/base.py", line 275, in get_new_connection
    connection = self.Database.connect(**conn_params)
  File "/home/ubuntu/Geo-Algo/venv/lib/python3.8/site-packages/psycopg2/__init__.py", line 122, in connect
    conn = _connect(dsn, connection_factory=connection_factory, **kwasync)
django.db.utils.OperationalError: connection to server at "13.126.174.197", port 5432 failed: Network is unreachable
	Is the server running on that host and accepting TCP/IP connections?

False
Outside market hours; skipping crossover check.
False
Outside market hours; skipping crossover check.
False
Outside market hours; skipping crossover check.
False
Outside market hours; skipping crossover check.
False
Outside market hours; skipping crossover check.
False
Outside market hours; skipping crossover check.
False
Breakout check complete.
False
Breakout check complete.
False
Breakout check complete.
False
Breakout check complete.
False
Breakout check complete.
False
Breakout check complete.
False
Breakout check complete.
False
Breakout check complete.
False
Breakout check complete.
False
Breakout check complete.
False
Breakout check complete.
False
Breakout check complete.
False
Breakout check complete.
False
Breakout check complete.
False
Breakout check complete.
False
Breakout check complete.
False
Breakout check complete.
False
Breakout check complete.
False
Breakout check complete.
False
Breakout check complete.
False
Breakout check complete.
False
Breakout check complete.
False
Outside market hours; skipping crossover check.
False
Outside market hours; skipping crossover check.
False
Outside market hours; skipping crossover check.
False
Outside market hours; skipping crossover check.
