False
Dhan token check complete.
False
Dhan token check complete.
False
Dhan token check complete.
False
Dhan token check complete.
False
Dhan token check complete.
False
Dhan token check complete.
False
Dhan token check complete.
False
Dhan token check complete.
False
Dhan token check complete.
False
Dhan token check complete.
False
Dhan token check complete.
False
Dhan token check complete.
False
Dhan token check complete.
False
Sending email to 8amitjain@gmail.com (‚ö†Ô∏è Dhan Token Expiring Soon)
Sending email to anandkene3073@gmail.com (‚ö†Ô∏è Dhan Token Expiring Soon)
Dhan token check complete.
False
Sending email to 8amitjain@gmail.com (‚ö†Ô∏è Dhan Token Expiring Soon)
Sending email to anandkene3073@gmail.com (‚ö†Ô∏è Dhan Token Expiring Soon)
Dhan token check complete.
False
Sending email to 8amitjain@gmail.com (‚ö†Ô∏è Dhan Token Expiring Soon)
Sending email to anandkene3073@gmail.com (‚ö†Ô∏è Dhan Token Expiring Soon)
Dhan token check complete.
False
Traceback (most recent call last):
  File "/home/ubuntu/Geo-Algo/venv/lib/python3.8/site-packages/django/db/backends/base/base.py", line 288, in ensure_connection
    self.connect()
  File "/home/ubuntu/Geo-Algo/venv/lib/python3.8/site-packages/django/utils/asyncio.py", line 26, in inner
    return func(*args, **kwargs)
  File "/home/ubuntu/Geo-Algo/venv/lib/python3.8/site-packages/django/db/backends/base/base.py", line 269, in connect
    self.connection = self.get_new_connection(conn_params)
  File "/home/ubuntu/Geo-Algo/venv/lib/python3.8/site-packages/django/utils/asyncio.py", line 26, in inner
    return func(*args, **kwargs)
  File "/home/ubuntu/Geo-Algo/venv/lib/python3.8/site-packages/django/db/backends/postgresql/base.py", line 275, in get_new_connection
    connection = self.Database.connect(**conn_params)
  File "/home/ubuntu/Geo-Algo/venv/lib/python3.8/site-packages/psycopg2/__init__.py", line 122, in connect
    conn = _connect(dsn, connection_factory=connection_factory, **kwasync)
psycopg2.OperationalError: connection to server at "13.126.174.197", port 5432 failed: Network is unreachable
	Is the server running on that host and accepting TCP/IP connections?


The above exception was the direct cause of the following exception:

Traceback (most recent call last):
  File "/home/ubuntu/Geo-Algo/manage.py", line 22, in <module>
    main()
  File "/home/ubuntu/Geo-Algo/manage.py", line 18, in main
    execute_from_command_line(sys.argv)
  File "/home/ubuntu/Geo-Algo/venv/lib/python3.8/site-packages/django/core/management/__init__.py", line 442, in execute_from_command_line
    utility.execute()
  File "/home/ubuntu/Geo-Algo/venv/lib/python3.8/site-packages/django/core/management/__init__.py", line 436, in execute
    self.fetch_command(subcommand).run_from_argv(self.argv)
  File "/home/ubuntu/Geo-Algo/venv/lib/python3.8/site-packages/django/core/management/base.py", line 412, in run_from_argv
    self.execute(*args, **cmd_options)
  File "/home/ubuntu/Geo-Algo/venv/lib/python3.8/site-packages/django/core/management/base.py", line 458, in execute
    output = self.handle(*args, **options)
  File "/home/ubuntu/Geo-Algo/market/management/commands/check_dhan_tokens.py", line 23, in handle
    for user in users:
  File "/home/ubuntu/Geo-Algo/venv/lib/python3.8/site-packages/django/db/models/query.py", line 398, in __iter__
    self._fetch_all()
  File "/home/ubuntu/Geo-Algo/venv/lib/python3.8/site-packages/django/db/models/query.py", line 1881, in _fetch_all
    self._result_cache = list(self._iterable_class(self))
  File "/home/ubuntu/Geo-Algo/venv/lib/python3.8/site-packages/django/db/models/query.py", line 91, in __iter__
    results = compiler.execute_sql(
  File "/home/ubuntu/Geo-Algo/venv/lib/python3.8/site-packages/django/db/models/sql/compiler.py", line 1560, in execute_sql
    cursor = self.connection.cursor()
  File "/home/ubuntu/Geo-Algo/venv/lib/python3.8/site-packages/django/utils/asyncio.py", line 26, in inner
    return func(*args, **kwargs)
  File "/home/ubuntu/Geo-Algo/venv/lib/python3.8/site-packages/django/db/backends/base/base.py", line 329, in cursor
    return self._cursor()
  File "/home/ubuntu/Geo-Algo/venv/lib/python3.8/site-packages/django/db/backends/base/base.py", line 305, in _cursor
    self.ensure_connection()
  File "/home/ubuntu/Geo-Algo/venv/lib/python3.8/site-packages/django/utils/asyncio.py", line 26, in inner
    return func(*args, **kwargs)
  File "/home/ubuntu/Geo-Algo/venv/lib/python3.8/site-packages/django/db/backends/base/base.py", line 288, in ensure_connection
    self.connect()
  File "/home/ubuntu/Geo-Algo/venv/lib/python3.8/site-packages/django/db/utils.py", line 91, in __exit__
    raise dj_exc_value.with_traceback(traceback) from exc_value
  File "/home/ubuntu/Geo-Algo/venv/lib/python3.8/site-packages/django/db/backends/base/base.py", line 288, in ensure_connection
    self.connect()
  File "/home/ubuntu/Geo-Algo/venv/lib/python3.8/site-packages/django/utils/asyncio.py", line 26, in inner
    return func(*args, **kwargs)
  File "/home/ubuntu/Geo-Algo/venv/lib/python3.8/site-packages/django/db/backends/base/base.py", line 269, in connect
    self.connection = self.get_new_connection(conn_params)
  File "/home/ubuntu/Geo-Algo/venv/lib/python3.8/site-packages/django/utils/asyncio.py", line 26, in inner
    return func(*args, **kwargs)
  File "/home/ubuntu/Geo-Algo/venv/lib/python3.8/site-packages/django/db/backends/postgresql/base.py", line 275, in get_new_connection
    connection = self.Database.connect(**conn_params)
  File "/home/ubuntu/Geo-Algo/venv/lib/python3.8/site-packages/psycopg2/__init__.py", line 122, in connect
    conn = _connect(dsn, connection_factory=connection_factory, **kwasync)
django.db.utils.OperationalError: connection to server at "13.126.174.197", port 5432 failed: Network is unreachable
	Is the server running on that host and accepting TCP/IP connections?

False
Sending email to 8amitjain@gmail.com (üö´ Your Dhan Access Token Has Expired)
Sending email to anandkene3073@gmail.com (üö´ Your Dhan Access Token Has Expired)
Dhan token check complete.
